<?xml version="1.0" encoding="utf-8"?>
<!-- This URDF was automatically created by SolidWorks to URDF Exporter! Originally created by Stephen Brawner (brawner@gmail.com) 
     Commit Version: 1.6.0-4-g7f85cfe  Build Version: 1.6.7995.38578
     For more information, please see http://wiki.ros.org/sw_urdf_exporter -->
<robot
  name="LRM_ARM_urdf2">
  <link
    name="base_link">
    <inertial>
      <origin
        xyz="-0.17179 -4.6466E-05 0.14175"
        rpy="0 0 0" />
      <mass
        value="1.58" />
      <inertia
        ixx="0.019015"
        ixy="9.5917E-06"
        ixz="0.0023844"
        iyy="0.028606"
        iyz="-5.2053E-06"
        izz="0.022815" />
    </inertial>
    <visual>
      <origin
        xyz="0 0 0"
        rpy="0 0 0" />
      <geometry>
        <mesh
          filename="package://LRM_ARM_urdf2/meshes/base_link.STL" />
      </geometry>
      <material
        name="">
        <color
          rgba="0.79216 0.81961 0.93333 1" />
      </material>
    </visual>
    <collision>
      <origin
        xyz="0 0 0"
        rpy="0 0 0" />
      <geometry>
        <mesh
          filename="package://LRM_ARM_urdf2/meshes/base_link.STL" />
      </geometry>
    </collision>
  </link>
  <link
    name="Link1">
    <inertial>
      <origin
        xyz="-3.3004E-06 -0.0029352 0.029475"
        rpy="0 0 0" />
      <mass
        value="0.037998" />
      <inertia
        ixx="3.3124E-05"
        ixy="-2.9288E-08"
        ixz="-4.1087E-08"
        iyy="3.2572E-05"
        iyz="3.3577E-07"
        izz="1.3405E-05" />
    </inertial>
    <visual>
      <origin
        xyz="0 0 0"
        rpy="0 0 0" />
      <geometry>
        <mesh
          filename="package://LRM_ARM_urdf2/meshes/Link1.STL" />
      </geometry>
      <material
        name="">
        <color
          rgba="0.79216 0.81961 0.93333 1" />
      </material>
    </visual>
    <collision>
      <origin
        xyz="0 0 0"
        rpy="0 0 0" />
      <geometry>
        <mesh
          filename="package://LRM_ARM_urdf2/meshes/Link1.STL" />
      </geometry>
    </collision>
  </link>
  <joint
    name="Joint1"
    type="revolute">
    <origin
      xyz="-0.034975 0 0.23608"
      rpy="0 1.0472 0" />
    <parent
      link="base_link" />
    <child
      link="Link1" />
    <axis
      xyz="0 0 -1" />
    <limit
      lower="-1.7453"
      upper="1.7453"
      effort="0"
      velocity="0" />
  </joint>
  <link
    name="Link2">
    <inertial>
      <origin
        xyz="0.0023653 0.057529 -6.7663E-05"
        rpy="0 0 0" />
      <mass
        value="0.084755" />
      <inertia
        ixx="0.00010536"
        ixy="-3.4002E-06"
        ixz="1.7658E-09"
        iyy="5.8005E-05"
        iyz="-2.508E-07"
        izz="8.0787E-05" />
    </inertial>
    <visual>
      <origin
        xyz="0 0 0"
        rpy="0 0 0" />
      <geometry>
        <mesh
          filename="package://LRM_ARM_urdf2/meshes/Link2.STL" />
      </geometry>
      <material
        name="">
        <color
          rgba="0.79216 0.81961 0.93333 1" />
      </material>
    </visual>
    <collision>
      <origin
        xyz="0 0 0"
        rpy="0 0 0" />
      <geometry>
        <mesh
          filename="package://LRM_ARM_urdf2/meshes/Link2.STL" />
      </geometry>
    </collision>
  </link>
  <joint
    name="Joint2"
    type="revolute">
    <origin
      xyz="0 0 0.046905"
      rpy="1.5708 0 3.1416" />
    <parent
      link="Link1" />
    <child
      link="Link2" />
    <axis
      xyz="0.93215 0 0.36208" />
    <limit
      lower="-1.7453"
      upper="1.7453"
      effort="0"
      velocity="0" />
  </joint>
  <link
    name="Link3">
    <inertial>
      <origin
        xyz="-0.00058256 -0.0028234 0.026135"
        rpy="0 0 0" />
      <mass
        value="0.035798" />
      <inertia
        ixx="2.6633E-05"
        ixy="7.4604E-08"
        ixz="4.3982E-07"
        iyy="2.4887E-05"
        iyz="3.8428E-07"
        izz="1.1534E-05" />
    </inertial>
    <visual>
      <origin
        xyz="0 0 0"
        rpy="0 0 0" />
      <geometry>
        <mesh
          filename="package://LRM_ARM_urdf2/meshes/Link3.STL" />
      </geometry>
      <material
        name="">
        <color
          rgba="0.79216 0.81961 0.93333 1" />
      </material>
    </visual>
    <collision>
      <origin
        xyz="0 0 0"
        rpy="0 0 0" />
      <geometry>
        <mesh
          filename="package://LRM_ARM_urdf2/meshes/Link3.STL" />
      </geometry>
    </collision>
  </link>
  <joint
    name="Joint3"
    type="revolute">
    <origin
      xyz="0 0.10351 0"
      rpy="1.5708 0 -3.1416" />
    <parent
      link="Link2" />
    <child
      link="Link3" />
    <axis
      xyz="0 0 -1" />
    <limit
      lower="-1.7453"
      upper="1.7453"
      effort="0"
      velocity="0" />
  </joint>
  <link
    name="Link4">
    <inertial>
      <origin
        xyz="0.0020924 0.05153 -2.0217E-05"
        rpy="0 0 0" />
      <mass
        value="0.051946" />
      <inertia
        ixx="7.0819E-05"
        ixy="-1.0721E-06"
        ixz="6.1521E-09"
        iyy="3.346E-05"
        iyz="-4.977E-09"
        izz="5.7666E-05" />
    </inertial>
    <visual>
      <origin
        xyz="0 0 0"
        rpy="0 0 0" />
      <geometry>
        <mesh
          filename="package://LRM_ARM_urdf2/meshes/Link4.STL" />
      </geometry>
      <material
        name="">
        <color
          rgba="0.79216 0.81961 0.93333 1" />
      </material>
    </visual>
    <collision>
      <origin
        xyz="0 0 0"
        rpy="0 0 0" />
      <geometry>
        <mesh
          filename="package://LRM_ARM_urdf2/meshes/Link4.STL" />
      </geometry>
    </collision>
  </link>
  <joint
    name="Joint4"
    type="revolute">
    <origin
      xyz="0 0 0.04307"
      rpy="1.5708 0 -3.1416" />
    <parent
      link="Link3" />
    <child
      link="Link4" />
    <axis
      xyz="0 0 1" />
    <limit
      lower="-1.7453"
      upper="1.7453"
      effort="0"
      velocity="0" />
  </joint>
  <link
    name="Link5">
    <inertial>
      <origin
        xyz="-0.00045301 -0.0025427 0.022086"
        rpy="0 0 0" />
      <mass
        value="0.039443" />
      <inertia
        ixx="3.4556E-05"
        ixy="5.9448E-08"
        ixz="5.6089E-07"
        iyy="3.2998E-05"
        iyz="8.195E-07"
        izz="1.1868E-05" />
    </inertial>
    <visual>
      <origin
        xyz="0 0 0"
        rpy="0 0 0" />
      <geometry>
        <mesh
          filename="package://LRM_ARM_urdf2/meshes/Link5.STL" />
      </geometry>
      <material
        name="">
        <color
          rgba="0.79216 0.81961 0.93333 1" />
      </material>
    </visual>
    <collision>
      <origin
        xyz="0 0 0"
        rpy="0 0 0" />
      <geometry>
        <mesh
          filename="package://LRM_ARM_urdf2/meshes/Link5.STL" />
      </geometry>
    </collision>
  </link>
  <joint
    name="Joint5"
    type="revolute">
    <origin
      xyz="0 0.10775 0"
      rpy="1.5708 0 3.1416" />
    <parent
      link="Link4" />
    <child
      link="Link5" />
    <axis
      xyz="0 0 -1" />
    <limit
      lower="-1.7453"
      upper="1.7453"
      effort="0"
      velocity="0" />
  </joint>
  <link
    name="Link6">
    <inertial>
      <origin
        xyz="0.0021294 0.056494 -0.00013588"
        rpy="0 0 0" />
      <mass
        value="0.081373" />
      <inertia
        ixx="0.00016127"
        ixy="-1.2534E-07"
        ixz="-1.628E-08"
        iyy="0.00011516"
        iyz="-6.7574E-07"
        izz="5.776E-05" />
    </inertial>
    <visual>
      <origin
        xyz="0 0 0"
        rpy="0 0 0" />
      <geometry>
        <mesh
          filename="package://LRM_ARM_urdf2/meshes/Link6.STL" />
      </geometry>
      <material
        name="">
        <color
          rgba="0.79216 0.81961 0.93333 1" />
      </material>
    </visual>
    <collision>
      <origin
        xyz="0 0 0"
        rpy="0 0 0" />
      <geometry>
        <mesh
          filename="package://LRM_ARM_urdf2/meshes/Link6.STL" />
      </geometry>
    </collision>
  </link>
  <joint
    name="Joint6"
    type="revolute">
    <origin
      xyz="0 0 0.04325"
      rpy="1.5708 0 3.1416" />
    <parent
      link="Link5" />
    <child
      link="Link6" />
    <axis
      xyz="0 0 1" />
    <limit
      lower="-1.7453"
      upper="1.7453"
      effort="0"
      velocity="0" />
  </joint>
  <link
    name="End_effector">
    <inertial>
      <origin
        xyz="-0.0021294 -0.00013588 -0.073887"
        rpy="0 0 0" />
      <mass
        value="0.081373" />
      <inertia
        ixx="0.00016127"
        ixy="1.628E-08"
        ixz="1.2534E-07"
        iyy="5.776E-05"
        iyz="-6.7574E-07"
        izz="0.00011516" />
    </inertial>
    <visual>
      <origin
        xyz="0 0 0"
        rpy="0 0 0" />
      <geometry>
        <mesh
          filename="package://LRM_ARM_urdf2/meshes/End_effector.STL" />
      </geometry>
      <material
        name="">
        <color
          rgba="0.79216 0.81961 0.93333 1" />
      </material>
    </visual>
    <collision>
      <origin
        xyz="0 0 0"
        rpy="0 0 0" />
      <geometry>
        <mesh
          filename="package://LRM_ARM_urdf2/meshes/End_effector.STL" />
      </geometry>
    </collision>
  </link>
  <joint
    name="none"
    type="fixed">
    <origin
      xyz="0 0.13038 0"
      rpy="1.5708 0 -3.1416" />
    <parent
      link="Link6" />
    <child
      link="End_effector" />
    <axis
      xyz="0 0 0" />
    <limit
      lower="1.74533"
      upper="1.74533"
      effort="0"
      velocity="0" />
  </joint>
</robot>