<?xml version="1.0" encoding="utf-8"?>
<!-- This URDF was automatically created by SolidWorks to URDF Exporter! Originally created by Stephen Brawner (brawner@gmail.com) 
     Commit Version: 1.6.0-4-g7f85cfe  Build Version: 1.6.7995.38578
     For more information, please see http://wiki.ros.org/sw_urdf_exporter -->
<robot
  name="LRM_ARM_simplified_fixed">
  <link
    name="base_link">
    <inertial>
      <origin
        xyz="-0.048104206841079 -4.90111673467908E-09 0.143557530418976"
        rpy="0 0 0" />
      <mass
        value="4.97178975391731" />
      <inertia
        ixx="0.0286525742966097"
        ixy="-5.05387354171124E-10"
        ixz="0.00709494743952162"
        iyy="0.0279823571540364"
        iyz="1.30205099336314E-09"
        izz="0.0260130342872084" />
    </inertial>
    <visual>
      <origin
        xyz="0 0 0"
        rpy="0 0 0" />
      <geometry>
        <mesh
          filename="package://LRM_ARM_simplified_fixed/meshes/base_link.STL" />
      </geometry>
      <material
        name="">
        <color
          rgba="0.792156862745098 0.819607843137255 0.933333333333333 1" />
      </material>
    </visual>
    <collision>
      <origin
        xyz="0 0 0"
        rpy="0 0 0" />
      <geometry>
        <mesh
          filename="package://LRM_ARM_simplified_fixed/meshes/base_link.STL" />
      </geometry>
    </collision>
  </link>
  <link
    name="link1">
    <inertial>
      <origin
        xyz="0 1.1102E-16 0.040987"
        rpy="0 0 0" />
      <mass
        value="0.17564" />
      <inertia
        ixx="0.00015754"
        ixy="-1.1079E-12"
        ixz="3.3034E-19"
        iyy="0.00014648"
        iyz="-6.7145E-20"
        izz="5.8551E-05" />
    </inertial>
    <visual>
      <origin
        xyz="0 0 0"
        rpy="0 0 0" />
      <geometry>
        <mesh
          filename="package://LRM_ARM_simplified_fixed/meshes/link1.STL" />
      </geometry>
      <material
        name="">
        <color
          rgba="0.79216 0.81961 0.93333 1" />
      </material>
    </visual>
    <collision>
      <origin
        xyz="0 0 0"
        rpy="0 0 0" />
      <geometry>
        <mesh
          filename="package://LRM_ARM_simplified_fixed/meshes/link1.STL" />
      </geometry>
    </collision>
  </link> 
  <joint
    name="joint1"
    type="revolute">
    <!--origin
      xyz="0 0 0.23432"
      rpy="0 0.7854 0" /-->
    <origin
      xyz="0 0 0.23432"
      rpy="0 0.7854 0" />
    <parent
      link="base_link" />
    <child
      link="link1" />
    <axis
      xyz="0 0 -1" />
    <limit
      lower="-1.7453"
      upper="1.7453"
      effort="4"
      velocity="0.12" />
  </joint>
  <link
    name="link2">
    <inertial>
      <origin
        xyz="-0.0088338 0.053407 1.8248E-08"
        rpy="0 0 0" />
      <mass
        value="0.16897" />
      <inertia
        ixx="0.00012053"
        ixy="1.0916E-05"
        ixz="1.3718E-11"
        iyy="0.00011686"
        iyz="4.5225E-11"
        izz="0.00012323" />
    </inertial>
    <visual>
      <origin
        xyz="0 0 0"
        rpy="0 0 0" />
      <geometry>
        <mesh
          filename="package://LRM_ARM_simplified_fixed/meshes/link2.STL" />
      </geometry>
      <material
        name="">
        <color
          rgba="0.79216 0.81961 0.93333 1" />
      </material>
    </visual>
    <collision>
      <origin
        xyz="0 0 0"
        rpy="0 0 0" />
      <geometry>
        <mesh
          filename="package://LRM_ARM_simplified_fixed/meshes/link2.STL" />
      </geometry>
    </collision>
  </link>
  <joint
    name="joint2"
    type="revolute"> <!-- 0.057205 -->
    <origin
      xyz="0 0 0.057205"
      rpy="1.5708 0 0" />
    <parent
      link="link1" />
    <child
      link="link2" />
    <axis
      xyz="0 0 1" />
    <limit
      lower="-1.7453"
      upper="1.7453"
      effort="4"
      velocity="0.12" />
  </joint>
  <link
    name="link3">
    <inertial> 
      <origin 
        xyz="-1.3878E-17 2.7756E-17 0.039326" 
        rpy="0 0 0" />
      <mass
        value="0.14908" />
      <inertia
        ixx="0.00010055"
        ixy="-1.1452E-12"
        ixz="1.135E-19"
        iyy="8.9207E-05"
        iyz="-3.4301E-20"
        izz="5.2789E-05" />
    </inertial>
    <visual>
      <origin
        xyz="0 0 0"
        rpy="0 0 0" />
      <geometry>
        <mesh
          filename="package://LRM_ARM_simplified_fixed/meshes/link3.STL" />
      </geometry>
      <material
        name="">
        <color
          rgba="0.79216 0.81961 0.93333 1" />
      </material>
    </visual>
    <collision>
      <origin
        xyz="0 0 0"
        rpy="0 0 0" />
      <geometry>
        <mesh
          filename="package://LRM_ARM_simplified_fixed/meshes/link3.STL" />
      </geometry>
    </collision>
  </link>
  <joint
    name="joint3" 
    type="revolute"> <!-- 0.08 -->
    <origin
      xyz="0 0.094805 0"
      rpy="-1.5708 0 0" />
    <parent
      link="link2" />
    <child
      link="link3" />
    <axis
      xyz="0 0 1" />
    <limit
      lower="-1.7453"
      upper="1.7453"
      effort="4"
      velocity="0.12" />
  </joint>
  <link
    name="link4"> 
    <inertial>
      <origin
        xyz="-0.005085 0.050535 -4.7282E-09"
        rpy="0 0 0" />
      <mass
        value="0.12789" />
      <inertia
        ixx="8.353E-05"
        ixy="4.6009E-06"
        ixz="7.7732E-12"
        iyy="7.3696E-05"
        iyz="-7.8057E-12"
        izz="8.0339E-05" />
    </inertial>
    <visual>
      <origin
        xyz="0 0 0"
        rpy="0 0 0" />
      <geometry>
        <mesh
          filename="package://LRM_ARM_simplified_fixed/meshes/link4.STL" />
      </geometry>
      <material
        name="">
        <color
          rgba="0.79216 0.81961 0.93333 1" />
      </material>
    </visual>
    <collision>
      <origin
        xyz="0 0 0"
        rpy="0 0 0" />
      <geometry>
        <mesh
          filename="package://LRM_ARM_simplified_fixed/meshes/link4.STL" />
      </geometry>
    </collision>
  </link>
  <joint
    name="joint4"
    type="revolute"> 
    <origin
      xyz="0 0 0.05207"
      rpy="1.5708 0 0" />
    <parent
      link="link3" />
    <child
      link="link4" />
    <axis
      xyz="0 0 -1" />
    <limit
      lower="-1.7453"
      upper="1.7453"
      effort="4"
      velocity="0.12" />
  </joint>
  <link
    name="link5">
    <inertial>
      <origin
        xyz="0 -2.7756E-17 0.041131"
        rpy="0 0 0" />
      <mass
        value="0.14106" />
      <inertia
        ixx="8.804E-05"
        ixy="-5.4409E-21"
        ixz="-1.6941E-20"
        iyy="7.669E-05"
        iyz="7.3341E-21"
        izz="5.1307E-05" />
    </inertial>
    <visual>
      <origin
        xyz="0 0 0"
        rpy="0 0 0" />
      <geometry>
        <mesh
          filename="package://LRM_ARM_simplified_fixed/meshes/link5.STL" />
      </geometry>
      <material
        name="">
        <color
          rgba="0.79216 0.81961 0.93333 1" />
      </material>
    </visual>
    <collision>
      <origin
        xyz="0 0 0"
        rpy="0 0 0" />
      <geometry>
        <mesh
          filename="package://LRM_ARM_simplified_fixed/meshes/link5.STL" />
      </geometry>
    </collision>
  </link>
  <joint
    name="joint5"
    type="revolute"> <!-- 0.07 -->
    <origin
      xyz="0 0.10822 0"
      rpy="-1.5708 0 0" />
    <parent
      link="link4" />
    <child
      link="link5" />
    <axis
      xyz="0 0 1" />
    <limit
      lower="-1.7453"
      upper="1.7453"
      effort="4"
      velocity="0.12" />
  </joint>
  <link
    name="link6">
    <inertial>
      <origin
        xyz="-0.0020164 0.062208 -2.7756E-17"
        rpy="0 0 0" />
      <mass
        value="0.10776" />
      <inertia
        ixx="0.00013214"
        ixy="-1.3313E-06"
        ixz="-1.4382E-20"
        iyy="6.5688E-05"
        iyz="1.8781E-20"
        izz="8.1577E-05" />
    </inertial>
    <visual>
      <origin
        xyz="0 0 0"
        rpy="0 0 0" />
      <geometry>
        <mesh
          filename="package://LRM_ARM_simplified_fixed/meshes/link6.STL" />
      </geometry>
      <material
        name="">
        <color
          rgba="0.79216 0.81961 0.93333 1" />
      </material>
    </visual>
    <collision>
      <origin
        xyz="0 0 0"
        rpy="0 0 0" />
      <geometry>
        <mesh
          filename="package://LRM_ARM_simplified_fixed/meshes/link6.STL" />
      </geometry>
    </collision>
  </link>
  <joint
    name="joint6"
    type="revolute">
    <origin
      xyz="0 0 0.05178"
      rpy="1.5708 0 0" />
    <parent
      link="link5" />
    <child
      link="link6" />
    <axis
      xyz="0 0 -1" />
    <limit
      lower="-1.7453"
      upper="1.7453"
      effort="4"
      velocity="0.12" />
  </joint>
  <link name="end_effector">
    <inertial>
        <origin xyz="0 0 0" rpy="0 0 0"/>
        <mass value="0.0"/>
        <inertia ixx="0.0" ixy="0.0" ixz="0.0" iyy="0.0" iyz="0.0" izz="0.0"/>
    </inertial>
    <visual>
        <origin xyz="0 0 0" rpy="0 0 0"/>
        <geometry>
            <sphere radius="0.0001"/>
        </geometry>
        <material name="blue">
            <color rgba="0 0 1 1"/>
        </material>
    </visual>
</link>
<joint name="dummy_joint" type="fixed">
    <origin xyz="0 0.13 0" rpy="-1.5708 0 0"/>
    <parent link="link6"/> <!-- Connect to the last link -->
    <child link="end_effector"/>
</joint>
</robot>